Workbook

Sheet 1. Чек-лист на вёрстку
A1: Чек-лист и результаты выполнения тестов: тестирование вёрстки
B3: Исходное состояние формы "Яндекс маршрут"
A4: № | B4: Описание проверки | C4: Яндекс Браузер 26.4.2.773 (64-bit) / Win11 / 800×600 | D4: Firefox 138.0.1 (64-bit) / Win11 / 1920×1080 | E4: Ссылка на баг-репорт
A5: ТВ1 | B5: Логотип "Яндекс Маршруты" Расположен в левом верхнем углу формы, шрифт жирный, черного цвета | C5: Passed | D5: Passed
A6: ТВ2 | B6: Надпись "Учебный режим "Расположена слева от логотипа "Яндекс Маршруты", выровнена вертикально по верхнему краю логотипа, шрифт серого цвета в верхнем регистре | C6: Failed | D6: Failed | E6: ='Баг-репорты'!A2 -> BAG_ ТВ2
A7: ТВ3 | B7: Форма ввода адресаПрямоугольник со скругленными краями, серого цвета | C7: Passed | D7: Passed
A8: ТВ4 | B8: Поле "Откуда"Расположено в форме ввода адреса, выравнивание по правому краю с отступом | C8: Passed | D8: Passed
A9: ТВ5 | B9: Кнопка отмены ввода Белый крест (Х) на сером круге, расположена справа от плейхольдера, выровнена по правому краю поля "Откуда" | C9: Passed | D9: Passed
A10: ТВ6 | B10: Маркер поля "Откуда"Красный кружок, расположен слева от поля "Откуда", выравнивание по правому краю с отступом | C10: Passed | D10: Passed
A11: ТВ7 | B11: Плейхольдер поля "Откуда"Текст серого цвета, выровнен по левому краю поля "Откуда" | C11: Passed | D11: Passed
A12: ТВ8 | B12: Кнопка отмены вводаБелый крест (Х) на сером круге, расположена справа от плейхольдера, выровнена по правому краю поля "Откуда" | C12: Passed | D12: Passed
A13: ТВ9 | B13: Маркер поля "Куда"Синий кружок, расположен слева от поля "Куда", выравнивание по правому краю с отступом | C13: Passed | D13: Passed
A14: ТВ10 | B14: Плейхольдер поля "Куда" Текст серого цвета, выровнен по левому краю поля "Куда" | C14: Passed | D14: Passed
A15: ТВ11 | B15: Кнопка отмены вводаБелый крест (Х) на сером круге, расположена справа от плейхольдера, выровнена по правому краю поля "Куда" | C15: Passed | D15: Passed
A16: ТВ12 | B16: Форма бронирования каршерингаПрямоугольник со скругленными углами, бордюр серого цвета | C16: Passed | D16: Passed
A17: ТВ13 | B17: Есть возможность очистки введённого значения | C17: Passed | D17: Passed
A18: ТВ14 | B18: После очистки поле возвращается в исходное состояние | C18: Passed | D18: Passed
... A21: ТВ17 | B21: Маркеры точек маршрута отображаются корректно для обоих полей | C21: Passed | D21: Passed
B22: Исходная формы бронирования Тариф: Раскошный
A23: № | B23: Описание проверки | C23: Яндекс Браузер 26.4.2.773 (64-bit) / Win11 / 800×600 | D23: Firefox 138.0.1 (64-bit) / Win11 / 1920×1080 | E23: Ссылка на баг-репорт
A24: ТВ21 | B24: Поля «Добавить права» и «Способ оплаты» по умолчанию пустые. | C24: Passed | D24: Passed
A25: ТВ22 | B25: Выпадающее меню «Требования к автомобилю» не ведёт на отдельную страницу, а открывает панель с параметрами на текущем экране. | C25: Passed | D25: Passed
A26: ТВ23 | B26: Группа кнопок выбора тарифаТри кнопки: "Повседневный", "Походный", "Роскошный" | C26: Passed | D26: Passed
A27: ТВ24 | B27: Выбранный тариф визуально подсвечивается (серым цветом / активным состоянием) | C27: Passed | D27: Passed
A28: ТВ25 | B28: Под блоком выбранного тарифа отображается информация о ближайшей машине | C28: Passed | D28: Passed
A29: ТВ26 | B29: Время в пути от пункта «Откуда» скрывается, если адрес в поле «Откуда» удалён | C29: Passed | D29: Passed
A30: ТВ27 | B30: Система автоматически определяет и выбирает ближайшую машину относительно пользователя | C30: Failed | D30: Failed | E30: ='Баг-репорты'!A3 -> BAG_ ТВ27
A31: ТВ28 | B31: При выборе машины её иконка на карте увеличивается, сверху появляется чёрная плашка с маркой автомобиля | C31: Failed | D31: Failed
A32: ТВ29 | B32: Плашка над выбранной машиной имеет чёрный фон, текст с маркой автомобиля — белого цвета | C32: Failed | D32: Failed
A33: ТВ31 | B33: Остальные свободные автомобили продолжают отображаться на карте обычными иконками | C33: Passed | D33: Passed
A34: ТВ32 | B34: При выборе конкретного тарифа на карте отображаются автомобили всех тарифов | C34: Failed | D34: Failed | E34: ='Баг-репорты'!A4 -> BAG_ ТВ32
A35: ТВ33 | B35: Пользователь может выбрать любую машину на карте, при этом информация о выбранном автомобиле обновляется на левой панели | C35: Failed | D35: Failed | E35: ='Баг-репорты'!A5 -> BAG_ ТВ33
A36: ТВ34 | B36: Если банковская карта не привязана, отображается текст «Добавить» вместо «Карта». Бронирование без привязанной карты невозможно | C36: Passed | D36: Passed
A37: ТВ35 | B37: При удалении адреса хотя бы в одном из полей («Откуда» или «Куда») отображается стартовая цена за минуту | C37: Failed | D37: Failed | E37: ='Баг-репорты'!A6 -> BAG_ ТВ35
A38: ТВ38 | B38: Остальные свободные автомобили Porsche 911 отображаются на карте обычными иконками. | C38: Passed | D38: Passed
A39: ТВ39 | B39: В блоке отображается подзаголовок «n мин. — 10 мин. бесплатного ожидания». | C39: Passed | D39: Passed
A40: ТВ40 | B40: В блоке отображаются дополнительные параметры: светомузыка, напитки для гостей | C40: Passed | D40: Passed
A41: ТВ41 | B41: Текст марки автомобиля расположен по центру | C41: Passed | D41: Passed
A42: ТВ42 | B42: Текст марки автомобиля написан большими буквами, чёрным цветом, жирным шрифтом | C42: Passed | D42: Passed
A43: ТВ43 | B43: Текст заголовка тарифа расположен под маркой автомобиля по центру | C43: Passed | D43: Passed
...

Sheet 2. Чек-лист «Способ оплаты» и «
A1: Чек-лист и результаты выполнения тестов: тестирование окон «Способ оплаты» и «Добавление карты»
A2: Поле "Способ оплаты"
A3: № | B3: Описание проверки | C3: Яндекс Браузер 26.4.2.773 (64-bit) / Win11 / 800×600 | D3: Ссылка на баг-репорт
A4: ТК1 | B4: По умолчанию поле не заполнено | C4: -
A5: ТК2 | B5: При нажатии на поле «Способ оплаты» открывается окно «Способ оплаты» с возможностью привязать новую карту или выбрать уже привязанную | C5: Passed
A6: ТК3 | B6: Чтобы добавить новую карту, нужно нажать на кнопку «Добавить карту», после этого открывается окно «Добавление карты» | C6: Passed
A7: ТК4 | B7: При успешном добавлении новой карты и нажатии на кнопку «Привязать» происходит переход обратно на форму выбора карт | C7: Passed
A8: ТК5 | B8: Чтобы выбрать карту, её нужно отметить и нажать на кнопку выхода из формы | C8: Passed
A9: ТК6 | B9: Если карта одна, она выбирается автоматически | C9: Passed
A10: ТК7 | B10: После выхода из формы поле «Способ оплаты» заполнено данными выбранной карты | C10: Passed
A11: ТК8 | B11: Возможно добавить 6 карт | C11: Passed
A12: ТК9 | B12: Возможно добавить 10 карт | C12: Passed
A13: ТК10 | B13: Возможно добавить 15 карт | C13: Passed
A14: ТК11 | B14: При добавлении большого количества карт (15+) окно «Способ оплаты» остаётся работоспособным (можно скроллить список карт) | C14: Passed
A15: ТК12 | B15: Пользователь может выбрать любую карту из списка после добавления 15+ карт | C15: Passed
A16: ТК13 | B16: После добавления большого количества карт (15+) последние 4 цифры каждой карты отображаются корректно | C16: Failed | D16: ='Баг-репорты'!A20 -> BAG_ ТК9
A17: ТК14 | B17: Когда карта добавлена, в интерфейсе отображаются последние 4 цифры её номера | C17: Failed
A18: ТК15 | B18: Окно «Добавление карты» закрывается при нажатии на крестик | C18: Passed
A19: ТК16 | B19: Окно закрывается, возврат в форму выбора карт при нажатии на кнопку «Отмена» | C19: Passed
A20: ТК17 | B20: Кнопка «Привязать» не активна при вводе менее 12 цифр в поле «Номер карты» | C20: Passed
A21: ТК18 | B21: Кнопка «Привязать» не активна при вводе менее 2 цифр в поле «Код» | C21: Passed
A22: ТК19 | B22: Данные в полях «Номер карты» и «Код» не сохраняются после ввода, закрытия и повторного открытия окна «Добавление карты» | C22: Passed
A23: Валидация поля «Номер карты» (позитив. пров)
A24: № | B24: Описание проверки | C24: Статус Окружение 1 | D24: Ссылка на баг-репорт
A25: ТК20 | B25: Карта добавилась после ввода 12 цифр в поле «Номер карты», двух цифр в поле «Код» и клика по кнопке «Привязать» | C25: Passed
A26: ТК21 | B26: Допустим формат ввода цифр — NNNN NNNN NNNN | C26: Passed
A27: ТК22 | B27: Пробелы ставятся автоматически между последовательностью из 4 цифр | C27: Failed | D27: ='Баг-репорты'!A21 -> BAG_ ТК18
A28: ТК23 | B28: Проверить, что ограничения для номера карты от 0000 до 9999 включительно | C28: Passed
A29: Валидация поля «Номер карты» (Негатив. пров)
A30: № | B30: Описание проверки | C30: Статус Окружение 1 | D30: Ссылка на баг-репорт
A31: ТК23 | B31: В поле «Номер карты» нельзя ввести больше 12 символов | C31: Failed | D31: ='Баг-репорты'!A37 -> BAG_ 1
A32: ТК24 | B32: В поле «Номер карты» нельзя ввести меньше 12 символов | C32: Failed | D32: ='Баг-репорты'!A38 -> BAG_ 2
A33: ТК25 | B33: Поле «Номер карты» не принимает буквы (латиница) | C33: Failed | D33: ='Баг-репорты'!A39 -> BAG_ 3
A34: ТК26 | B34: Поле «Номер карты» не принимает буквы (кириллица) | C34: Failed | D34: ='Баг-репорты'!A40 -> BAG_ 4
A35: ТК27 | B35: Поле «Номер карты» не принимает спецсимволы | C35: Failed | D35: ='Баг-репорты'!A41 -> BAG_ 5
A36: ТК28 | B36: Поле «Номер карты» не принимает ввод пробелов вручную | C36: Failed | D36: ='Баг-репорты'!A22 -> BAG_ ТК24
A37: ТК29 | B37: Поле «Номер карты» не принимает знаки препинания | C37: Failed | D37: ='Баг-репорты'!A42 -> BAG_ 6
A38: ТК30 | B38: Поле «Номер карты» не принимает дробные числа с точкой(12.5) | C38: Failed | D38: ='Баг-репорты'!A43 -> BAG_ 7
A39: ТК31 | B39: Поле «Номер карты» не принимает дробные числа с запятой (12,5) | C39: Failed | D39: ='Баг-репорты'!A44 -> BAG_ 8
A40: ТК32 | B40: Поле «Номер карты» не принимае строки с буквами и спецсимволами | C40: Failed | D40: ='Баг-репорты'!A45 -> BAG_ 9
...

Sheet 2. Тест-кейсы на кнопку «Заброн
A1: Тест-кейсы и тестирование: логика кнопки «Забронировать»
A3: id тест-кейса | B3: Название тест-кейса | C3: Предусловия | D3: Описание шага | E3: ОР | F3: Окружение | G3: Статус | H3: Ссылка на баг- репорт
A4: t-1 | B4: Проверка логики кнопки бронирования при заполнении всех обязательных полей формы бронирования | C4: 1. Перейти на тестовый стенд 2. Ввести в поле Откуда ""Хамовнический вал, 18"" 3. Ввести в поле Куда ""Усачева, 3"" 4. Выбрать режим Свой 5. Выбрать вид транспорта Каршеринг 6. Нажать на кнопку Забронировать | D4: 1)Нажать на поле Добавить права 2)"В окне Добавление прав ввести: Имя - Ира Фамилия - Улма Дата: 24.03.1999 Номер:1212123456 3)Нажать кнопку добавить 4)Нажать в окне подтверждения 5)Нажать на поле Способ оплаты 6)Нажать на кнопку добавить карту 7)"Ввести данные карты: Номер карты - 123412341234 Код - 12" 8)Нажать кнопку привязать карту 9)Выбрать карту и закрыть окно 10)Нажать на кнопку бронирования | E4: Текст на кнопке "Забронировать Маршрут составит .. км и займет .. мин" При нажатии на кнопку открывается окно "Машина забронирована" | F4: Яндекс Браузер 26.4.2.773 (64-bit) / Win11 / 800×600 | G4: Passed
A7: t-2 | B7: Проверка логики кнопки бронирования при заполнении всех обязательных полей формы бронирования, кроме прав | C7: 1. Перейти на тестовый стенд 2. Ввести в поле Откуда ""Хамовнический вал, 18"" 3. Ввести в поле Куда ""Усачева, 3"" 4. Выбрать режим Свой 5. Выбрать вид транспорта Каршеринг 6. Нажать на кнопку Забронировать | D7: 1Нажать на поле Способ оплаты 2Нажать на кнопку добавить карту 3"Ввести данные карты: Номер карты - 123412341234 Код - 12" 4Нажать кнопку привязать карту 5Выбрать карту и закрыть окно 6Нажать на кнопку бронирования | E7: Открылось окно "Добавление прав" " | F7: Яндекс Браузер 26.4.2.773 (64-bit) / Win11 / 800×600 | G7: Failed | H7: ='Баг-репорты'!A24 -> BAG_ t2
A12: t-3 | B12: Проверка логики кнопки бронирования при заполнении всех обязательных полей формы бронирования, кроме способа оплаты | C12: 1. Перейти на тестовый стенд 2. Ввести в поле Откуда ""Хамовнический вал, 18"" 3. Ввести в поле Куда ""Усачева, 3"" 4. Выбрать режим Свой 5. Выбрать вид транспорта Каршеринг 6. Нажать на кнопку Забронировать | D12: 1Нажать на поле Добавить права 2"В окне Добавление прав ввести: Имя - Владимир Фамилия - Набоков Дата: 24.04.1889 Номер: 0102345678" 3Нажать кнопку добавить 4Нажать в окне подтверждения 5Нажать на кнопку бронирования | E12: Открылось окно "Добавление карты" | F12: Яндекс Браузер 26.4.2.773 (64-bit) / Win11 / 800×600 | G12: Failed | H12: ='Баг-репорты'!A25 -> BAG_ t3
A17: t-4 | B17: Проверка логики кнопки бронирования при заполнении всех обязательных полей формы бронирования, адреса удалены | C17: 1. Перейти на тестовый стенд 2. Ввести в поле Откуда ""Хамовнический вал, 18"" 3. Ввести в поле Куда ""Усачева, 3"" 4. Выбрать режим Свой 5. Выбрать вид транспорта Каршеринг 6. Нажать на кнопку Забронировать | D17: 1Очистить поле Откуда 2Очистить поле Куда 3Нажать на поле Добавить права 4"В окне Добавление прав ввести: Имя - Владимир Фамилия - Набоков Дата: 24.04.1889 Номер: 0102345678" 5Нажать кнопку добавить 6Нажать в окне подтверждения 7Нажать на поле Способ оплаты 8Нажать на кнопку добавить карту 9"Ввести данные карты: Номер карты - 123412341234 Код - 12" 10Нажать кнопку привязать карту 11Выбрать карту и закрыть окно 12Нажать на кнопку бронирования | E17: При нажатии на кнопку открылось окно "Машина забронирована" | F17: Яндекс Браузер 26.4.2.773 (64-bit) / Win11 / 800×600 | G17: Blocked | H17: ='Баг-репорты'!A26 -> BAG_ t4
A22: t-5 | B22: Проверка логики кнопки бронирования при не заполнении всех обязательных полей формы бронирования, адреса удалены | C22: 1. Перейти на тестовый стенд 2. Ввести в поле Откуда ""Хамовнический вал, 18"" 3. Ввести в поле Куда ""Усачева, 3"" 4. Выбрать режим Свой 5. Выбрать вид транспорта Каршеринг 6. Нажать на кнопку Забронировать | D22: 1Очистить поле Откуда 2Очистить поле Куда 3Нажать на кнопку бронирования | E22: При нажатии на кнопку открылось окно "Добавление прав" | F22: Яндекс Браузер 26.4.2.773 (64-bit) / Win11 / 800×600 | G22: Blocked | H22: ='Баг-репорты'!A26 -> BAG_ t4

Sheet Баг-репорты
A1: ID | B1: Название БР | C1: Приоритет | D1: Предусловия | E1: Шаги воспроизведения | F1: Ожидаемый результат | G1: Фактический результат | H1: Окружение
A2: BAG_ ТВ2 | B2: Надпись «Учебный тренажёр» расположена под логотипом | C2: Низкий | D2: 1)Открыта форма бронирования каршеринга 2)Выбран тариф «Роскошный» | E2: 1)Посмотреть на шапку страницы. | F2: Надпись «УЧЕБНЫЙ ТРЕНАЖЁР» расположена справа от логотипа «Яндекс Маршруты», выровнена по верхнему краю логотипа, шрифт серого цвета, в верхнем регистре. | G2: Надпись «Учебный тренажёр» расположена ниже логотипа «Яндекс Маршруты», по центру или правому краю (под логотипом). | H2: ОС: Windows 11 Браузер: Яндекс Браузер 26.4.2.773 (64-bit) разрешение экрана 800×600;
A3: BAG_ ТВ27 | B3: Отсутствует автоматическое выделение и визуальное обозначение выбранной машины на карте | C3: Критический | D3: 1)Открыта форма бронирования каршеринга 2)Выбран тариф «Роскошный» | E3: 1)Заполнить поле «Откуда» ( Усачева, 3). 2)Заполнить поле «Куда» ( Зубовский бульвар, 37). 3)Посмотреть на карту и поведение иконок автомобилей. | F3: Автоматически выбирается и выделяется ближайшая машина. При выборе машины иконка увеличивается. Над машиной появляется чёрная плашка с белым текстом марки автомобиля.ю. | G3: Автоматического выделения нет. При выборе машины ничего не происходит — иконка не увеличивается, плашка не появляется. | H3: ОС: Windows 11 Браузер: Яндекс Браузер 26.4.2.773 (64-bit) разрешение экрана 800×600;
A4: BAG_ ТВ32 | B4: Автомобили других тарифов исчезают при выборе тарифа | C4: Критический | D4: 1)Открыта форма бронирования каршеринга 2)Выбран тариф «Роскошный» | E4: 1)Обратить внимание на отображение автомобилей на карте. | F4: На карте отображаются автомобили всех тарифов (Повседневный, Походный, Роскошный). | G4: Отображаются только автомобили выбранного тарифа («Роскошный»), автомобили других тарифов исчезают. | H4: ОС: Windows 11 Браузер: Яндекс Браузер 26.4.2.773 (64-bit) разрешение экрана 800×600;
A5: BAG_ ТВ33 | B5: При выборе автомобиля на карте не обновляется информация об автомобиле на левой панели | C5: Критический | D5: 1)Открыта форма бронирования каршеринга 2)Выбран тариф «Роскошный» | E5: Нажать на любой автомобиль на карте Проверить отображение информации на левой панели | F5: При выборе автомобиля на карте на левой панели должна отображаться полная информация о выбранном автомобиле (марка, модель, стоимость, характеристики и т.д.) | G5: Информация об автомобиле на левой панели не обновляется. Отображается только марка автомобиля в верхней части интерфейса. | H5: ОС: Windows 11 Браузер: Яндекс Браузер 26.4.2.773 (64-bit) разрешение экрана 800×600;
A6: BAG_ ТВ35 | B6: При удалении адреса поле подсвечивается ошибкой вместо показа стартовой цены за минуту | C6: Средний | D6: 1)Открыта форма бронирования каршеринга 2)Выбран тариф «Роскошный» | E6: 1)Заполнить поле «Откуда» ( Усачева, 3). 2)Заполнить поле «Куда» ( Зубовский бульвар, 37) 3)Удалить адрес в одном из полей (нажать на крестик). | F6: Отображается стартовая цена за минуту на кнопке «Забронировать» (без ошибок валидации). | G6: Поле, из которого удалили адрес, подсвечивается оранжевой/красной рамкой и появляется текст «Введите адрес». | H6: ОС: Windows 11 Браузер: Яндекс Браузер 26.4.2.773 (64-bit) разрешение экрана 800×600;
A7: BAG_ ТВ63 | B7: Отсутствует зелёная галочка и успешное состояние поля после верификации прав | C7: Средний | D7: 1)Открыта форма бронирования каршеринга 2)Выбран тариф «Роскошный» | E7: 1)Нажать на поле «Добавить права». 2)Заполнить данные и отправить документы. 3)Нажать кнопку «Понятно».. 4) Дождаться результата верификации (успешного). | F7: После успешной верификации: Текст меняется на «Права» Рамка поля светится зелёным цветом Справа внутри поля появляется зелёная галочка | G7: Зелёная галочка и зелёная рамка не появляются. | H7: ОС: Windows 11 Браузер: Яндекс Браузер 26.4.2.773 (64-bit) разрешение экрана 800×600;
A8: BAG_ ТВ65 | B8: Отсутствует негативный сценарий верификации прав | C8: Средний | D8: 1)Открыта форма бронирования каршеринга 2)Выбран тариф «Роскошный» | E8: 1)Нажать на поле «Добавить права». 2)Заполнить данные и отправить документы. 3)Нажать кнопку «Понятно».. 4) Дождаться результата верификации (неуспешной верификации).. | F8: Рамка поля светится красным цветом Справа появляется красный крестик Появляется сообщение «Ваши документы не прошли верификацию. Попробуйте ещё раз» | G8: Негативное состояние не отрабатывается. Красная рамка, крестик и сообщение об ошибке отсутствуют. | H8: ОС: Windows 11 Браузер: Яндекс Браузер 26.4.2.773 (64-bit) разрешение экрана 800×600;
A9: BAG_ ТВ74 | B9: Текст «Способ оплаты» отображается серым цветом вместо чёрного | C9: Низкий | D9: 1)Открыта форма бронирования каршеринга 2)Выбран тариф «Роскошный» | E9: 1) Посмотреть на поле «Способ оплаты» (без добавленной карты). | F9: Текст «Способ оплаты» имеет серый цвет. | G9: Текст «Способ оплаты» имеет чёрный цвет. | H9: ОС: Windows 11 Браузер: Яндекс Браузер 26.4.2.773 (64-bit) разрешение экрана 800×600;
A10: BAG_ ТВ91 | B10: В группе «Развлечься» используются переключатели вместо радиокнопок | C10: Средний | D10: 1)Открыта форма бронирования каршеринга 2)Выбран тариф «Роскошный» | E10: 1)Открыть панель «Требования к заказу». 2)Посмотреть на группу «Развлечься» («Шампанское для пассажиров», «Вино для пассажиров»). | F10: Варианты в группе «Развлечься» реализованы через радиокнопки. | G10: Варианты реализованы через переключатели | H10: ОС: Windows 11 Браузер: Яндекс Браузер 26.4.2.773 (64-bit) разрешение экрана 800×600;
A11: BAG_ ТВ92 | B11: В группе «Развлечься» можно выбрать несколько вариантов одновременно | C11: Средний | D11: 1)Открыта форма бронирования каршеринга 2)Выбран тариф «Роскошный» | E11: 1)Открыть панель «Требования к заказу» 2)В группе «Развлечься» выбрать оба варианта («Шампанское для пассажиров» и «Вино для пассажиров»). | F11: Можно выбрать только один вариант из группы «Развлечься». | G11: Возможно выбрать все варианты одновременно. | H11: ОС: Windows 11 Браузер: Яндекс Браузер 26.4.2.773 (64-bit) разрешение экрана 800×600;
A12: BAG_ ТВ103 | B12: При удалении адреса форма сбрасывается в начальное состояние | C12: Критический | D12: 1)Открыта форма бронирования каршеринга 2)Выбран тариф «Роскошный» | E12: Заполнить поля «Откуда» и «Куда». Удалить адрес в одном из полей (нажать на крестик). | F12: Форма остаётся в текущем состоянии (тариф, машина, требования к заказу и т.д. сохраняются). На кнопке «Забронировать» отображается текст «Забронировать» (или «Забронировать. Маршрут составит .. км и займет .. мин»). | G12: При удалении хотя бы одного адреса вся форма сбрасывается в исходное состояние (как на втором скриншоте): пропадает выбранный тариф, панели и т.д. | H12: ОС: Windows 11 Браузер: Яндекс Браузер 26.4.2.773 (64-bit) разрешение экрана 800×600;
... A45: BAG_ 9 | B45: Поле «Номер карты» принимает строки с буквами и спецсимволами (например, a1@) | C45: Критический | D45: 1)Открыта форма бронирования каршеринга 2)Выбран тариф «Роскошный» | E45: 1.Открыть окно «Добавление карты». 2.В поле «Номер карты» ввести строку «a1@». | F45: Отображаются только цифры («1»), буквы и спецсимволы игнорируются. | G45: Отображаются все символы («a1@»). | H45: ОС: Windows 11 Браузер: Яндекс Браузер 26.4.2.773 (64-bit) разрешение экрана 800×600;
